Workbook

Sheet Info
A1: Name | B1: Symbol | C1: Exchange | D1: Category | E1: Price
A2: KODEX KOFR금리액티브(합성) | B2: 423160 | C2: KRX | D2: Cash | E2: =INDEX(Price!B:B,MATCH(TRUE,INDEX(ISNUMBER(Price!B$2:B$1000),0),0)+1)
A3: KODEX CD금리액티브(합성) | B3: 459580 | C3: KRX | D3: Cash | E3: =INDEX(Price!C:C,MATCH(TRUE,INDEX(ISNUMBER(Price!C$2:C$1000),0),0)+1)
A4: TIGER CD1년금리액티브(합성) | B4: 475630 | C4: KRX | D4: Cash | E4: =INDEX(Price!D:D,MATCH(TRUE,INDEX(ISNUMBER(Price!D$2:D$1000),0),0)+1)
A5: KRW | B5: KRW_KRW | C5: KRX | D5: Cash | E5: 1
A6: SGOV | B6: SGOV | C6: NYSE Arca | D6: Cash | E6: =INDEX(Price!E:E,MATCH(TRUE,INDEX(ISNUMBER(Price!E$2:E$1000),0),0)+1)
A7: STRK | B7: STRK | C7: NASDAQ | D7: Cash | E7: =INDEX(Price!F:F,MATCH(TRUE,INDEX(ISNUMBER(Price!F$2:F$1000),0),0)+1)
A8: STRC | B8: STRC | C8: NASDAQ | D8: Cash | E8: =INDEX(Price!G:G,MATCH(TRUE,INDEX(ISNUMBER(Price!G$2:G$1000),0),0)+1)
A9: STRD | B9: STRD | C9: NASDAQ | D9: Cash | E9: =INDEX(Price!H:H,MATCH(TRUE,INDEX(ISNUMBER(Price!H$2:H$1000),0),0)+1)
A10: STRF | B10: STRF | C10: NASDAQ | D10: Cash | E10: =INDEX(Price!I:I,MATCH(TRUE,INDEX(ISNUMBER(Price!I$2:I$1000),0),0)+1)
A11: USDT | B11: USDT_KRW | C11: Upbit | D11: Cash | E11: =INDEX(Price!J:J,MATCH(TRUE,INDEX(ISNUMBER(Price!J$2:J$1000),0),0)+1)
A12: USD | B12: USD_KRW | C12: Forex | D12: Cash | E12: =INDEX(Price!K:K,MATCH(TRUE,INDEX(ISNUMBER(Price!K$2:K$1000),0),0)+1)
A13: KINDEX KRX금현물 | B13: 411060 | C13: KRX | D13: Gold | E13: =INDEX(Price!L:L,MATCH(TRUE,INDEX(ISNUMBER(Price!L$2:L$1000),0),0)+1)
A14: ACE 미국10년국채액티브(H) | B14: 0085P0 | C14: KRX | D14: Bonds | E14: =INDEX(Price!M:M,MATCH(TRUE,INDEX(ISNUMBER(Price!M$2:M$1000),0),0)+1)
A15: ACE 미국장기채액티브 | B15: 476760 | C15: KRX | D15: Bonds | E15: =INDEX(Price!N:N,MATCH(TRUE,INDEX(ISNUMBER(Price!N$2:N$1000),0),0)+1)
A16: VGIT | B16: VGIT | C16: NASDAQ | D16: Bonds | E16: =INDEX(Price!O:O,MATCH(TRUE,INDEX(ISNUMBER(Price!O$2:O$1000),0),0)+1)
A17: VGLT | B17: VGLT | C17: NASDAQ | D17: Bonds | E17: =INDEX(Price!P:P,MATCH(TRUE,INDEX(ISNUMBER(Price!P$2:P$1000),0),0)+1)
A18: VTIP | B18: VTIP | C18: NASDAQ | D18: Bonds | E18: =INDEX(Price!Q:Q,MATCH(TRUE,INDEX(ISNUMBER(Price!Q$2:Q$1000),0),0)+1)
A19: TIGER MSCI US 리츠(합성H) | B19: 182480 | C19: KRX | D19: Kor Stock | E19: =INDEX(Price!R:R,MATCH(TRUE,INDEX(ISNUMBER(Price!R$2:R$1000),0),0)+1)
A20: TIGER KOSDAQ150 | B20: 232080 | C20: KRX | D20: Kor Stock | E20: =INDEX(Price!S:S,MATCH(TRUE,INDEX(ISNUMBER(Price!S$2:S$1000),0),0)+1)
A21: ACE 미국S&P500 | B21: 360200 | C21: KRX | D21: Kor Stock | E21: =INDEX(Price!T:T,MATCH(TRUE,INDEX(ISNUMBER(Price!T$2:T$1000),0),0)+1)
A22: KBSTAR 200 Total Return | B22: 361580 | C22: KRX | D22: Kor Stock | E22: =INDEX(Price!U:U,MATCH(TRUE,INDEX(ISNUMBER(Price!U$2:U$1000),0),0)+1)
A23: KODEX S&P500 | B23: 379800 | C23: KRX | D23: Kor Stock | E23: =INDEX(Price!V:V,MATCH(TRUE,INDEX(ISNUMBER(Price!V$2:V$1000),0),0)+1)
A24: KODEX 미국나스닥100(TR) | B24: 379810 | C24: KRX | D24: Kor Stock | E24: =INDEX(Price!W:W,MATCH(TRUE,INDEX(ISNUMBER(Price!W$2:W$1000),0),0)+1)
A25: KINDEX S&P500 3070 Blend | B25: 438080 | C25: KRX | D25: Kor Stock | E25: =INDEX(Price!X:X,MATCH(TRUE,INDEX(ISNUMBER(Price!X$2:X$1000),0),0)+1)
A26: 유비케어 | B26: 032620 | C26: KOSDAQ | D26: Kor Stock | E26: =INDEX(Price!Y:Y,MATCH(TRUE,INDEX(ISNUMBER(Price!Y$2:Y$1000),0),0)+1)
A27: KoAct 코스닥액티브 | B27: 0163Y0 | C27: KRX | D27: Kor Stock | E27: =INDEX(Price!Z:Z,MATCH(TRUE,INDEX(ISNUMBER(Price!Z$2:Z$1000),0),0)+1)
A28: QQQM | B28: QQQM | C28: NASDAQ | D28: US Stock | E28: =INDEX(Price!AA:AA,MATCH(TRUE,INDEX(ISNUMBER(Price!AA$2:AA$1000),0),0)+1)
A29: SCHD | B29: SCHD | C29: NYSE Arca | D29: US Stock | E29: =INDEX(Price!AB:AB,MATCH(TRUE,INDEX(ISNUMBER(Price!AB$2:AB$1000),0),0)+1)
A30: SPYM | B30: SPYM | C30: NYSE Arca | D30: US Stock | E30: =INDEX(Price!AC:AC,MATCH(TRUE,INDEX(ISNUMBER(Price!AC$2:AC$1000),0),0)+1)
A31: MSTR | B31: MSTR | C31: NASDAQ | D31: US Stock | E31: =INDEX(Price!AD:AD,MATCH(TRUE,INDEX(ISNUMBER(Price!AD$2:AD$1000),0),0)+1)
A32: VIG | B32: VIG | C32: NYSE Arca | D32: US Stock | E32: =INDEX(Price!AE:AE,MATCH(TRUE,INDEX(ISNUMBER(Price!AE$2:AE$1000),0),0)+1)
A33: Bitcoin | B33: BTC_USDT | C33: Crypto | D33: Crypto | E33: =INDEX(Price!AF:AF,MATCH(TRUE,INDEX(ISNUMBER(Price!AF$2:AF$1000),0),0)+1)
A34: Ethereum | B34: ETH_USDT | C34: Crypto | D34: Crypto | E34: =INDEX(Price!AG:AG,MATCH(TRUE,INDEX(ISNUMBER(Price!AG$2:AG$1000),0),0)+1)

Sheet Price
A1: Date | B1: 423160 | C1: 459580 | D1: 475630 | E1: SGOV | F1: Strategy Prf | G1: Strategy Prf A | H1: Strategy Prf D | I1: Strategy Prf F | J1: USDT_KRW Upbit | K1: USD_KRW | L1: 411060 | M1: 0085P0 | N1: 476760 | O1: VGIT | P1: VGLT | Q1: VTIP | R1: 182480 | S1: 232080 | T1: 360200 | U1: 361580 | V1: 379800 | W1: 379810 | X1: 438080 | Y1: UB Care | Z1: 0163Y0 | AA1: QQQM | AB1: SCHD | AC1: SPYM | AD1: Strategy | AE1: VIG | AF1: Bitcoin | AG1: Ethereum
A2: 04/29/2026 | B2: 110635 | C2: 1073620 | D2: 1065150 | E2: 100.66 | J2: 1477.63 | K2: 1477.4301 | L2: 30205 | M2: 10740 | N2: 9980 | O2: 59.439999 | P2: 55.220001 | Q2: 50.369999 | R2: 13575 | S2: 20900 | T2: 26490 | U2: 57410 | V2: 23885 | W2: 26600 | X2: 14435 | Y2: 4140 | Z2: 13235 | AA2: 270.76001 | AB2: 31.309999 | AC2: 83.760002 | AD2: 165.71001 | AE2: 225.35001 | AF2: 77011.203 | AG2: 2322.73
A3: 04/28/2026 | B3: 110865 | C3: 1075680 | D3: 1064810 | E3: 100.64 | J3: 1474.67 | K3: 1473.88 | L3: 30490 | M3: 10730 | N3: 9945 | O3: 59.509998 | P3: 55.18 | Q3: 50.380001 | R3: 13500 | S3: 20835 | T3: 26525 | U3: 57010 | V3: 23985 | W3: 26660 | X3: 14395 | Y3: 4210 | Z3: 13120 | AA3: 273.51001 | AB3: 31.129999 | AC3: 84.169998 | AD3: 169.2 | AE3: 225.99001 | AF3: 76573 | AG3: 2273.8999
A4: 04/27/2026 | B4: 110860 | C4: 1075595 | D4: 1064730 | E4: 100.64 | J4: 1471.9 | K4: 1471.38 | L4: 30900 | M4: 10735 | N4: 9990 | O4: 59.580002 | P4: 55.43 | Q4: 50.34 | R4: 13565 | S4: 21100 | T4: 26475 | U4: 56765 | V4: 23940 | W4: 26715 | X4: 14380 | Y4: 4200 | Z4: 13240 | AA4: 273.38 | AB4: 31.200001 | AC4: 84.029999 | AD4: 171.02 | AE4: 226.83 | AF4: 77614.719 | AG4: 2319.49
A5: 04/26/2026 | E5: 100.64 | J5: 1476.81 | K5: 1476.3199 | O5: 59.580002 | P5: 55.43 | Q5: 50.34 | AA5: 273.38 | AB5: 31.200001 | AC5: 84.029999 | AD5: 171.02 | AE5: 226.83 | AF5: 78012.289 | AG5: 2330.1899
A6: 04/25/2026 | E6: 100.64 | J6: 1476.83 | K6: 1476.3199 | O6: 59.580002 | P6: 55.43 | Q6: 50.34 | AA6: 273.38 | AB6: 31.200001 | AC6: 84.029999 | AD6: 171.02 | AE6: 226.83 | AF6: 77489.82 | AG6: 2314.8999
A7: 04/24/2026 | B7: 110845 | C7: 1075515 | D7: 1064690 | E7: 100.61 | J7: 1485.08 | K7: 1483.6801 | L7: 31070 | M7: 10815 | N7: 10085 | O7: 59.48 | P7: 55.32 | Q7: 50.240002 | R7: 13600 | S7: 20695 | T7: 26510 | U7: 55465 | V7: 23970 | W7: 26550 | X7: 14450 | Y7: 4160 | Z7: 13045 | AA7: 268.22 | AB7: 31.42 | AC7: 83.379997 | AD7: 172.47 | AE7: 227.78999 | AF7: 77850.312 | AG7: 2316.6799
A8: 04/23/2026 | B8: 110825 | C8: 1075430 | D8: 1064570 | E8: 100.6099 | J8: 1480.77 | K8: 1479.98 | L8: 31255 | M8: 10790 | N8: 10045 | O8: 59.575001 | P8: 55.529999 | Q8: 50.200001 | R8: 13420 | S8: 20115 | T8: 26435 | U8: 55675 | V8: 23900 | W8: 26415 | X8: 14415 | Y8: 4140 | Z8: 12785 | AA8: 269.86499 | AB8: 31.264601 | AC8: 83.705002 | AD8: 177.575 | AE8: 227.69501 | AF8: 77658.109 | AG8: 2322.46
A9: 04/22/2026 | B9: 110810 | C9: 1075180 | D9: 1064305 | E9: 100.59 | J9: 1477.93 | K9: 1477.38 | L9: 31540 | M9: 10785 | N9: 10045 | O9: 59.52 | P9: 55.32 | Q9: 50.139999 | R9: 13620 | S9: 20260 | T9: 26325 | U9: 55060 | V9: 23800 | W9: 26155 | X9: 14365 | Y9: 4190 | Z9: 12920 | AA9: 265.31 | AB9: 30.98 | AC9: 82.870003 | AD9: 163.97 | AE9: 226.17 | AF9: 78044.297 | AG9: 2394.4099
A10: 04/21/2026 | B10: 110810 | C10: 1075100 | D10: 1064220 | E10: 100.57 | J10: 1471.02 | K10: 1469.78 | L10: 31550 | M10: 10755 | N10: 10035 | O10: 59.720001 | P10: 55.639999 | Q10: 50.18 | R10: 13805 | S10: 20300 | T10: 26295 | U10: 54895 | V10: 23775 | W10: 26050 | X10: 14325 | Y10: 4235 | Z10: 12880 | AA10: 266.29999 | AB10: 31.030001 | AC10: 83.419998 | AD10: 170.81 | AE10: 227.33 | AF10: 75955.75 | AG10: 2316.1699
A11: 04/20/2026 | B11: 110800 | C11: 1075020 | D11: 1064140 | E11: 100.56 | J11: 1472.56 | K11: 1476.38 | L11: 31715 | M11: 10805 | N11: 10040 | O11: 59.759998 | P11: 55.650002 | Q11: 50.16 | R11: 13750 | S11: 20125 | T11: 26275 | U11: 53500 | V11: 23760 | W11: 26010 | X11: 14360 | Y11: 4270 | Z11: 12835 | AA11: 267.13 | AB11: 31.049999 | AC11: 83.580002 | AD11: 166.52 | AE11: 227.46001 | AF11: 74814.031 | AG11: 2287.1899
A12: 04/19/2026 | E12: 100.56 | J12: 1467.43 | K12: 1465.6801 | O12: 59.759998 | P12: 55.650002 | Q12: 50.16 | AA12: 267.13 | AB12: 31.049999 | AC12: 83.580002 | AD12: 166.52 | AE12: 227.46001 | AF12: 75543.82 | AG12: 2340.0601
A13: 04/18/2026 | E13: 100.56 | J13: 1467.41 | K13: 1465.6801 | O13: 59.759998 | P13: 55.650002 | Q13: 50.16 | AA13: 267.13 | AB13: 31.049999 | AC13: 83.580002 | AD13: 166.52 | AE13: 227.46001 | AF13: 77177.344 | AG13: 2415.6001
A14: 04/17/2026 | B14: 110795 | C14: 1074935 | D14: 1064090 | E14: 100.53 | J14: 1483.7 | K14: 1483.29 | L14: 31850 | M14: 10795 | N14: 10010 | O14: 59.529999 | P14: 55.189999 | Q14: 50.150002 | R14: 13555 | S14: 19950 | T14: 26220 | U14: 53220 | V14: 23705 | W14: 25905 | X14: 14355 | Y14: 4330 | Z14: 12830 | AA14: 263.69 | AB14: 30.809999 | AC14: 82.580002 | AD14: 148.94 | AE14: 224.88 | AF14: 75100.492 | AG14: 2341.46
A15: 04/16/2026 | B15: 110770 | C15: 1074855 | D15: 1063990 | E15: 100.53 | J15: 1472.77 | K15: 1472.1801 | L15: 31935 | M15: 10770 | N15: 10035 | O15: 59.59 | P15: 55.490002 | Q15: 50.139999 | R15: 13440 | S15: 19945 | T15: 26050 | U15: 53605 | V15: 23560 | W15: 25770 | X15: 14265 | Y15: 4275 | Z15: 12670 | AA15: 262.48001 | AB15: 30.65 | AC15: 82.379997 | AD15: 143.53999 | AE15: 224.37 | AF15: 74986.633 | AG15: 2353.46
A16: 04/15/2026 | B16: 110755 | C16: 1074610 | D16: 1063725 | E16: 100.51 | J16: 1475.21 | K16: 1474.28 | L16: 31920 | M16: 10785 | N16: 10085 | O16: 59.66 | P16: 55.709999 | Q16: 50.16 | R16: 13440 | S16: 19805 | T16: 25795 | U16: 52470 | V16: 23315 | W16: 25290 | X16: 14210 | Y16: 4200 | Z16: 12570 | AA16: 258.78 | AB16: 30.709999 | AC16: 81.739998 | AD16: 137.41 | AE16: 223.87 | AF16: 73896.68 | AG16: 2319.9299
A17: 04/14/2026 | B17: 110755 | C17: 1074525 | D17: 1063650 | E17: 100.51 | J17: 1476 | K17: 1475.98 | L17: 31665 | M17: 10810 | N17: 10100 | O17: 59.529999 | P17: 55.43 | Q17: 50.130001 | R17: 13280 | S17: 19115 | T17: 25610 | U17: 51180 | V17: 23155 | W17: 25005 | X17: 14180 | Y17: 4195 | Z17: 12210 | AA17: 254.17 | AB17: 30.74 | AC17: 80.739998 | AD17: 132.36 | AE17: 223.25999 | AF17: 74630.172 | AG17: 2381.7
A18: 04/13/2026 | B18: 110740 | C18: 1074445 | D18: 1063575 | E18: 100.5 | J18: 1488.5 | K18: 1488.01 | L18: 31605 | M18: 10830 | N18: 10070 | O18: 59.43 | P18: 55.259998 | Q18: 50.049999 | R18: 13250 | S18: 18925 | T18: 25340 | U18: 49700 | V18: 22905 | W18: 24675 | X18: 14130 | Y18: 4080 | Z18: 11945 | AA18: 251.60001 | AB18: 30.559999 | AC18: 79.959999 | AD18: 128.64 | AE18: 221.47 | AF18: 70719.602 | AG18: 2184.3647
A19: 04/12/2026 | E19: 100.5 | J19: 1484.9 | K19: 1482.7 | O19: 59.43 | P19: 55.259998 | Q19: 50.049999 | AA19: 251.60001 | AB19: 30.559999 | AC19: 79.959999 | AD19: 128.64 | AE19: 221.47 | AF19: 71612.836 | AG19: 2213.9731
A20: 04/11/2026 | E20: 100.5 | J20: 1485.27 | K20: 1482.7 | O20: 59.43 | P20: 55.259998 | Q20: 50.049999 | AA20: 251.60001 | AB20: 30.559999 | AC20: 79.959999 | AD20: 128.64 | AE20: 221.47 | AF20: 72785.508 | AG20: 2235.5547
A21: 04/10/2026 | B21: 110735 | C21: 1074365 | D21: 1063530 | E21: 100.46 | J21: 1484.2 | K21: 1483.39 | L21: 31705 | M21: 10815 | N21: 10070 | O21: 59.5 | P21: 55.400002 | Q21: 50.029999 | R21: 13205 | S21: 18940 | T21: 25385 | U21: 50185 | V21: 22945 | W21: 24680 | X21: 14125 | Y21: 3965 | Z21: 11820 | AA21: 251.23 | AB21: 30.940001 | AC21: 80.019997 | AD21: 128.86 | AE21: 222.82001 | AF21: 71779.523 | AG21: 2185.9409
A22: 04/09/2026 | B22: 110715 | C22: 1074280 | D22: 1063410 | J22: 1481.08 | K22: 1479.79 | L22: 31450 | M22: 10815 | N22: 10090 | R22: 13090 | S22: 18815 | T22: 25200 | U22: 49415 | V22: 22790 | W22: 24490 | X22: 14040 | Y22: 3905 | Z22: 11470 | AF22: 71050.125 | AG22: 2184.8811
A23: 04/08/2026 | B23: 110705 | C23: 1074040 | D23: 1063175 | J23: 1476.08 | K23: 1476.6801 | L23: 31955 | M23: 10770 | N23: 10100 | R23: 12975 | S23: 19060 | T23: 25090 | U23: 50365 | V23: 22690 | W23: 24440 | X23: 14000 | Y23: 3930 | Z23: 11640 | AF23: 71686.461 | AG23: 2246.2927
A24: 04/07/2026 | B24: 110700 | C24: 1073955 | D24: 1063085 | E24: 100.44 | J24: 1504.88 | K24: 1503.78 | L24: 31340 | M24: 10925 | N24: 10215 | O24: 59.279999 | P24: 55.299999 | Q24: 49.990002 | R24: 12845 | S24: 18125 | T24: 24870 | U24: 46835 | V24: 22490 | W24: 24055 | X24: 14070 | Y24: 3865 | Z24: 11040 | AA24: 242.32001 | AB24: 30.639999 | AC24: 77.559998 | AD24: 127.69 | AE24: 216.82001 | AF24: 68491.773 | AG24: 2099.5032
A25: 04/06/2026 | B25: 110690 | C25: 1073875 | D25: 1063025 | E25: 100.43 | J25: 1504.55 | K25: 1505.3 | L25: 31570 | M25: 10930 | N25: 10195 | O25: 59.389999 | P25: 55.369999 | Q25: 49.990002 | R25: 12895 | S25: 18215 | T25: 24870 | U25: 46225 | V25: 22490 | W25: 24065 | X25: 14095 | Y25: 3905 | Z25: 11175 | AA25: 240.86 | AB25: 30.559999 | AC25: 77.190002 | AD25: 119.83 | AE25: 216.02 | AF25: 68833.695 | AG25: 2122.707
A26: 04/05/2026 | E26: 100.43 | J26: 1509.99 | K26: 1510.54 | O26: 59.389999 | P26: 55.369999 | Q26: 49.990002 | AA26: 240.86 | AB26: 30.559999 | AC26: 77.190002 | AD26: 119.83 | AE26: 216.02 | AF26: 66869.234 | AG26: 2040.6427
A27: 04/04/2026 | E27: 100.43 | J27: 1509.96 | K27: 1514 | O27: 59.389999 | P27: 55.369999 | Q27: 49.990002 | AA27: 240.86 | AB27: 30.559999 | AC27: 77.190002 | AD27: 119.83 | AE27: 216.02 | AF27: 66977.219 | AG27: 2054.1541
A28: 04/03/2026 | B28: 110685 | C28: 1073795 | D28: 1062995 | E28: 100.43 | J28: 1506.73 | K28: 1507.01 | L28: 31715 | M28: 10950 | N28: 10250 | O28: 59.389999 | P28: 55.369999 | Q28: 49.990002 | R28: 12850 | S28: 18485 | T28: 24830 | U28: 45550 | V28: 22455 | W28: 23995 | X28: 14075 | Y28: 3970 | Z28: 11450 | AA28: 240.86 | AB28: 30.559999 | AC28: 77.190002 | AD28: 119.83 | AE28: 216.02 | AF28: 66814.047 | AG28: 2064.5886
A29: 04/02/2026 | B29: 110660 | C29: 1073715 | D29: 1062855 | E29: 100.39 | J29: 1517.23 | K29: 1516.28 | L29: 31115 | M29: 11000 | N29: 10235 | O29: 59.310001 | P29: 55.099998 | Q29: 49.869999 | R29: 12720 | S29: 18500 | T29: 24760 | U29: 44295 | V29: 22365 | W29: 23835 | X29: 14085 | Y29: 3900 | Z29: 11500 | AA29: 240.57001 | AB29: 30.51 | AC29: 77.120003 | AD29: 122.78 | AE29: 215.67999 | AF29: 66666.375 | AG29: 2049.2795
A30: 04/01/2026 | B30: 110645 | C30: 1073470 | D30: 1062580 | E30: 100.66 | J30: 1498.51 | K30: 1498.98 | L30: 31835 | M30: 10955 | N30: 10255 | O30: 59.549999 | P30: 55.360001 | Q30: 49.950001 | R30: 12620 | S30: 19615 | T30: 24760 | U30: 46485 | V30: 22390 | W30: 23895 | X30: 14040 | Y30: 4040 | Z30: 12330 | AA30: 237.62 | AB30: 30.68 | AC30: 76.540001 | AD30: 124.8 | AE30: 215.06 | AF30: 69139.344 | AG30: 2153.3337
A31: 03/31/2026 | B31: 110640 | C31: 1073390 | D31: 1062510 | E31: 100.66 | J31: 1527.52 | K31: 1528.84 | L31: 31540 | M31: 11130 | N31: 10415 | O31: 59.43 | P31: 55.369999 | Q31: 49.939999 | R31: 12455 | S31: 18585 | T31: 24575 | U31: 42580 | V31: 22215 | W31: 23515 | X31: 14110 | Y31: 3935 | Z31: 11190 | AA31: 229.87 | AB31: 30.48 | AC31: 74.379997 | AD31: 121.44 | AE31: 210.7 | AF31: 67382.852 | AG31: 2058.1614
A32: 03/30/2026 | B32: 110640 | C32: 1073305 | D32: 1062455 | E32: 100.65 | J32: 1517.62 | K32: 1518.39 | L32: 30965 | M32: 10960 | N32: 10240 | O32: 59.169998 | P32: 54.700001 | Q32: 49.799999 | R32: 12440 | S32: 19645 | T32: 24275 | U32: 44530 | V32: 21945 | W32: 23335 | X32: 13920 | Y32: 4020 | Z32: 11840 | AA32: 231.61 | AB32: 30.440001 | AC32: 74.639999 | AD32: 126.03 | AE32: 210.73 | AF32: 67344.125 | AG32: 2046.7147
A33: 03/29/2026 | E33: 100.65 | J33: 1506.83 | K33: 1508.36 | O33: 59.169998 | P33: 54.700001 | Q33: 49.799999 | AA33: 231.61 | AB33: 30.440001 | AC33: 74.639999 | AD33: 126.03 | AE33: 210.73 | AF33: 66516.578 | AG33: 1998.9926
A34: 03/28/2026 | E34: 100.65 | J34: 1506.96 | K34: 1508.36 | O34: 59.169998 | P34: 54.700001 | Q34: 49.799999 | AA34: 231.61 | AB34: 30.440001 | AC34: 74.639999 | AD34: 126.03 | AE34: 210.73 | AF34: 66369.766 | AG34: 2000.5927
A35: 03/27/2026 | B35: 110850 | C35: 1075530 | D35: 1062395 | E35: 100.62 | J35: 1504.08 | K35: 1504.76 | L35: 30325 | M35: 10925 | N35: 10215 | O35: 59.09 | P35: 54.939999 | Q35: 49.73 | R35: 12635 | S35: 20265 | T35: 24680 | U35: 45930 | V35: 22320 | W35: 23795 | X35: 13990 | Y35: 4055 | Z35: 12380 | AA35: 236.21001 | AB35: 30.620001 | AC35: 75.919998 | AD35: 132.92999 | AE35: 214.22 | AF35: 68611.562 | AG35: 2060.5498
A36: 03/26/2026 | B36: 110825 | C36: 1075445 | D36: 1062280 | E36: 100.61 | J36: 1503.64 | K36: 1503.89 | L36: 30100 | M36: 10940 | N36: 10225 | O36: 59.43 | P36: 55.389999 | Q36: 49.779999 | R36: 12625 | S36: 20080 | T36: 24850 | U36: 46160 | V36: 22460 | W36: 24090 | X36: 14080 | Y36: 3990 | Z36: 12430 | AA36: 241.98 | AB36: 30.540001 | AC36: 77.300003 | AD36: 139.13 | AE36: 216.19 | AF36: 70007.242 | AG36: 2120.0759
A37: 03/25/2026 | B37: 110815 | C37: 1075200 | D37: 1062030 | E37: 100.61 | J37: 1498.2 | K37: 1498.42 | L37: 30815 | M37: 10895 | N37: 10195 | O37: 59.240002 | P37: 54.900002 | Q37: 49.77 | R37: 12640 | S37: 20525 | T37: 24805 | U37: 47810 | V37: 22425 | W37: 24035 | X37: 14035 | Y37: 4030 | Z37: 12740 | AA37: 240.42 | AB37: 30.639999 | AC37: 76.870003 | AD37: 136.25 | AE37: 215.25 | AF37: 71017.008 | AG37: 2165.8577
A38: 03/24/2026 | B38: 110810 | C38: 1075115 | D38: 1061940 | E38: 100.58 | J38: 1495.29 | K38: 1495.76 | L38: 29520 | M38: 10845 | N38: 10130 | O38: 59.41 | P38: 55.119999 | Q38: 49.82 | R38: 12660 | S38: 19825 | T38: 24625 | U38: 47215 | V38: 22270 | W38: 23945 | X38: 13960 | Y38: 4000 | Z38: 12380 | AA38: 242.07001 | AB38: 30.540001 | AC38: 77.129997 | AD38: 138.2 | AE38: 214.94 | AF38: 71024.859 | AG38: 2159.73
A39: 03/23/2026 | B39: 110795 | C39: 1075030 | D39: 1061875 | E39: 100.58 | J39: 1510.16 | K39: 1510.38 | L39: 29265 | M39: 10955 | N39: 10200 | O39: 59.27 | P39: 54.779999 | Q39: 49.919998 | R39: 12595 | S39: 19450 | T39: 24625 | U39: 45830 | V39: 22260 | W39: 23890 | X39: 14000 | Y39: 3900 | Z39: 12080 | AA39: 239.64 | AB39: 30.389999 | AC39: 76.330002 | AD39: 135.66 | AE39: 212.96001 | AF39: 68516.547 | AG39: 2052.4087
A40: 03/22/2026 | E40: 100.58 | J40: 1504.96 | K40: 1504.83 | O40: 59.27 | P40: 54.779999 | Q40: 49.919998 | AA40: 239.64 | AB40: 30.389999 | AC40: 76.330002 | AD40: 135.66 | AE40: 212.96001 | AF40: 68955.305 | AG40: 2097.7837
...

Sheet Volume
A1: Date | B1: 423160 | C1: 459580 | D1: 475630 | E1: SGOV | F1: Strategy Prf | G1: Strategy Prf A | H1: Strategy Prf D | I1: Strategy Prf F | J1: USDT_KRW Upbit | K1: 411060 | L1: 0085P0 | M1: 476760 | N1: VGIT | O1: VGLT | P1: VTIP | Q1: 182480 | R1: 232080 | S1: 360200 | T1: 361580 | U1: 379800 | V1: 379810 | W1: 438080 | X1: UB Care | Y1: 0163Y0 | Z1: QQQM | AA1: SCHD | AB1: SPYM | AC1: Strategy | AD1: VIG | AE1: Bitcoin | AF1: Ethereum
A2: 04/29/2026 | B2: 87650 | C2: 257082 | D2: 16083 | E2: 13143600 | J2: 45604205 | K2: 1665518 | L2: 304673 | M2: 304305 | N2: 2391000 | O2: 1617900 | P2: 3982300 | Q2: 15248 | R2: 3648332 | S2: 343926 | T2: 111115 | U2: 9703852 | V2: 2222476 | W2: 436832 | X2: 130714 | Y2: 1698407 | Z2: 2783900 | AA2: 15827500 | AB2: 5970700 | AC2: 13758700 | AD2: 634000 | AE2: 33763131392 | AF2: 14832651264
A3: 04/28/2026 | B3: 105848 | C3: 321112 | D3: 21151 | E3: 14179800 | J3: 64463314 | K3: 2101445 | L3: 168641 | M3: 437432 | N3: 3622500 | O3: 1278900 | P3: 2134200 | Q3: 23261 | R3: 3033109 | S3: 392630 | T3: 58228 | U3: 9004712 | V3: 3539018 | W3: 502936 | X3: 149183 | Y3: 2348434 | Z3: 2548900 | AA3: 19412400 | AB3: 6702000 | AC3: 13192100 | AD3: 980400 | AE3: 32246755328 | AF3: 14489027584
A4: 04/27/2026 | B4: 418317 | C4: 342422 | D4: 24783 | E4: 16619600 | J4: 53239990 | K4: 1926980 | L4: 173383 | M4: 613021 | N4: 5077000 | O4: 1015500 | P4: 1830200 | Q4: 27815 | R4: 4700103 | S4: 620765 | T4: 173831 | U4: 12779883 | V4: 4452083 | W4: 674109 | X4: 196621 | Y4: 3376301 | Z4: 4119500 | AA4: 19277400 | AB4: 7849600 | AC4: 14066300 | AD4: 856400 | AE4: 29738954752 | AF4: 14676025344
A5: 04/26/2026 | E5: 16619600 | J5: 47830344 | N5: 5077000 | O5: 1015500 | P5: 1830200 | Z5: 4119500 | AA5: 19277400 | AB5: 7849600 | AC5: 14066300 | AD5: 856400 | AE5: 16415970304 | AF5: 7258625024
A6: 04/25/2026 | E6: 16619600 | J6: 48244531 | N6: 5077000 | O6: 1015500 | P6: 1830200 | Z6: 4119500 | AA6: 19277400 | AB6: 7849600 | AC6: 14066300 | AD6: 856400 | AE6: 30157539328 | AF6: 11489953792
A7: 04/24/2026 | B7: 394758 | C7: 299992 | D7: 15725 | E7: 14468700 | J7: 53905483 | K7: 1629066 | L7: 184241 | M7: 311262 | N7: 2356700 | O7: 1594600 | P7: 2834200 | Q7: 30647 | R7: 4209409 | S7: 404098 | T7: 35603 | U7: 14704551 | V7: 4285361 | W7: 564310 | X7: 123626 | Y7: 2667686 | Z7: 4085800 | AA7: 16770500 | AB7: 11433700 | AC7: 19446300 | AD7: 1021200 | AE7: 37218836480 | AF7: 17283524608
A8: 04/23/2026 | B8: 443981 | C8: 264942 | D8: 17197 | E8: 1962552 | J8: 68385864 | K8: 1740322 | L8: 241501 | M8: 315598 | N8: 334635 | O8: 161160 | P8: 89320 | Q8: 15687 | R8: 4013734 | S8: 494936 | T8: 92498 | U8: 18369145 | V8: 7722667 | W8: 470304 | X8: 114126 | Y8: 3292221 | Z8: 498663 | AA8: 2487599 | AB8: 1100430 | AC8: 2389321 | AD8: 52811 | AE8: 42982682624 | AF8: 20749443072
A9: 04/22/2026 | B9: 380692 | C9: 246722 | D9: 23243 | E9: 13857000 | J9: 67238990 | K9: 1376002 | L9: 118839 | M9: 278044 | N9: 2088300 | O9: 1171700 | P9: 1381900 | Q9: 22778 | R9: 3094879 | S9: 491281 | T9: 39788 | U9: 12639685 | V9: 4340335 | W9: 458644 | X9: 194309 | Y9: 2375811 | Z9: 3184200 | AA9: 17862400 | AB9: 11091400 | AC9: 22007800 | AD9: 811100 | AE9: 43896451072 | AF9: 20925952000
A10: 04/21/2026 | B10: 376041 | C10: 240379 | D10: 20142 | E10: 19015500 | J10: 52139584 | K10: 1276117 | L10: 121819 | M10: 187222 | N10: 1798800 | O10: 1001100 | P10: 1779800 | Q10: 25945 | R10: 3391175 | S10: 456992 | T10: 41383 | U10: 15872798 | V10: 4677901 | W10: 510979 | X10: 207423 | Y10: 2703020 | Z10: 2844200 | AA10: 17212100 | AB10: 10754000 | AC10: 22067200 | AD10: 1146400 | AE10: 37588004864 | AF10: 18054975488
A11: 04/20/2026 | B11: 368799 | C11: 253727 | D11: 19383 | E11: 20507900 | J11: 71453328 | K11: 1369852 | L11: 193454 | M11: 258547 | N11: 2077700 | O11: 1501100 | P11: 1869100 | Q11: 22508 | R11: 2682619 | S11: 779573 | T11: 161181 | U11: 16131404 | V11: 4702526 | W11: 559298 | X11: 290627 | Y11: 2241902 | Z11: 3087300 | AA11: 20078900 | AB11: 10923700 | AC11: 52025900 | AD11: 1003600 | AE11: 33511088128 | AF11: 17192800256
A12: 04/19/2026 | E12: 20507900 | J12: 44755273 | N12: 2077700 | O12: 1501100 | P12: 1869100 | Z12: 3087300 | AA12: 20078900 | AB12: 10923700 | AC12: 52025900 | AD12: 1003600 | AE12: 26062688256 | AF12: 14171198464
A13: 04/18/2026 | E13: 19913441 | J13: 77986368 | N13: 2077704 | O13: 1501064 | P13: 1868158 | Z13: 3079789 | AA13: 20006357 | AB13: 10920225 | AC13: 51836230 | AD13: 1003557 | AE13: 52618678272 | AF13: 26238980096
A14: 04/17/2026 | B14: 428111 | C14: 335009 | D14: 28105 | E14: 16340900 | J14: 74107914 | K14: 1077490 | L14: 154283 | M14: 330856 | N14: 2241100 | O14: 1059400 | P14: 1547200 | Q14: 20105 | R14: 2076719 | S14: 1001911 | T14: 53821 | U14: 20001113 | V14: 3506517 | W14: 422046 | X14: 200148 | Y14: 2136798 | Z14: 2714600 | AA14: 17370900 | AB14: 9259900 | AC14: 17568600 | AD14: 819000 | AE14: 38779744256 | AF14: 20091017216
A15: 04/16/2026 | B15: 458932 | C15: 251564 | D15: 24949 | E15: 19570600 | J15: 57216588 | K15: 1503918 | L15: 145481 | M15: 246801 | N15: 1665600 | O15: 655200 | P15: 2615400 | Q15: 14478 | R15: 1887981 | S15: 1228087 | T15: 356766 | U15: 22846526 | V15: 9122672 | W15: 439013 | X15: 372166 | Y15: 2063914 | Z15: 4085800 | AA15: 18957500 | AB15: 7983800 | AC15: 13736800 | AD15: 974800 | AE15: 38480834560 | AF15: 17057978368
A16: 04/15/2026 | B16: 479529 | C16: 268663 | D16: 20473 | E16: 29760800 | J16: 76098926 | K16: 1550689 | L16: 116523 | M16: 279323 | N16: 2789600 | O16: 703900 | P16: 1653900 | Q16: 18111 | R16: 2557837 | S16: 853508 | T16: 228834 | U16: 22968179 | V16: 5516306 | W16: 486969 | X16: 263059 | Y16: 2874684 | Z16: 5655100 | AA16: 18629200 | AB16: 6486400 | AC16: 20575500 | AD16: 849700 | AE16: 50782285824 | AF16: 22665617408
A17: 04/14/2026 | B17: 467518 | C17: 342946 | D17: 30665 | E17: 20052800 | J17: 79527921 | K17: 1290798 | L17: 129718 | M17: 260079 | N17: 1798700 | O17: 1023300 | P17: 1520300 | Q17: 14084 | R17: 1802076 | S17: 416960 | T17: 209952 | U17: 13222149 | V17: 7812184 | W17: 382648 | X17: 429425 | Y17: 1833832 | Z17: 2650200 | AA17: 19365000 | AB17: 8351100 | AC17: 12370800 | AD17: 1106800 | AE17: 51496124416 | AF17: 26388662272
A18: 04/13/2026 | B18: 377677 | C18: 408260 | D18: 24640 | E18: 18632500 | J18: 35553201 | K18: 931627 | L18: 154707 | M18: 193381 | N18: 2069200 | O18: 1196000 | P18: 1368500 | Q18: 15031 | R18: 1679468 | S18: 818819 | T18: 62515 | U18: 17644166 | V18: 11635233 | W18: 378322 | X18: 323472 | Y18: 1743546 | Z18: 2152400 | AA18: 19600500 | AB18: 10499600 | AC18: 13056400 | AD18: 775300 | AE18: 31244175360 | AF18: 12960235520
A19: 04/12/2026 | E19: 18632500 | J19: 36343255 | N19: 2069200 | O19: 1196000 | P19: 1368500 | Z19: 2152400 | AA19: 19600500 | AB19: 10499600 | AC19: 13056400 | AD19: 775300 | AE19: 26668367872 | AF19: 15391669248
A20: 04/11/2026 | E20: 18632500 | J20: 40046514 | N20: 2069200 | O20: 1196000 | P20: 1368500 | Z20: 2152400 | AA20: 19600500 | AB20: 10499600 | AC20: 13056400 | AD20: 775300 | AE20: 35748843520 | AF20: 15758045184
A21: 04/10/2026 | B21: 388472 | C21: 281526 | D21: 20225 | E21: 17627300 | J21: 51134258 | K21: 1081460 | L21: 187534 | M21: 310643 | N21: 1636900 | O21: 1181100 | P21: 1865600 | Q21: 16571 | R21: 1721813 | S21: 549420 | T21: 238549 | U21: 13649677 | V21: 8350808 | W21: 337880 | X21: 88460 | Y21: 2654407 | Z21: 2740700 | AA21: 31662900 | AB21: 10821700 | AC21: 14356600 | AD21: 936500 | AE21: 39727886336 | AF21: 18018801664
A22: 04/09/2026 | B22: 422329 | C22: 1062139 | D22: 22037 | E22: 23669681 | J22: 54262102 | K22: 1108820 | L22: 73857 | M22: 159782 | N22: 2343866 | O22: 1319784 | P22: 2519701 | Q22: 21085 | R22: 2731676 | S22: 385715 | T22: 78449 | U22: 16634947 | V22: 3743368 | W22: 331289 | X22: 74282 | Y22: 1906961 | Z22: 5573674 | AA22: 30048876 | AB22: 15424627 | AC22: 17038311 | AD22: 1005473 | AE22: 38292852736 | AF22: 18261708800
A23: 04/08/2026 | B23: 426139 | C23: 467662 | D23: 95548 | E23: 17189201 | J23: 94263892 | K23: 1787815 | L23: 184344 | M23: 449824 | N23: 2900423 | O23: 1821377 | P23: 2126996 | Q23: 78876 | R23: 3229745 | S23: 532527 | T23: 790292 | U23: 17704916 | V23: 7994154 | W23: 575818 | X23: 127674 | Y23: 3314307 | Z23: 2713861 | AA23: 17946976 | AB23: 18726293 | AC23: 13413685 | AD23: 1129479 | AE23: 49017290752 | AF23: 25511000064
A24: 04/07/2026 | B24: 403862 | C24: 287769 | D24: 51847 | E24: 23076600 | J24: 55406273 | K24: 1279483 | L24: 99256 | M24: 276507 | N24: 2518300 | O24: 1376500 | P24: 2894900 | Q24: 7841 | R24: 3010019 | S24: 594926 | T24: 93081 | U24: 13261490 | V24: 5563451 | W24: 373009 | X24: 92003 | Y24: 2916008 | Z24: 2726800 | AA24: 21949800 | AB24: 15007400 | AC24: 18364800 | AD24: 1369000 | AE24: 35623415808 | AF24: 17329305600
A25: 04/06/2026 | B25: 379739 | C25: 302147 | D25: 53003 | E25: 22593000 | J25: 48823176 | K25: 1118437 | L25: 116055 | M25: 469542 | N25: 13322300 | O25: 2063500 | P25: 2781100 | Q25: 11584 | R25: 3198690 | S25: 837899 | T25: 103058 | U25: 14486417 | V25: 8121836 | W25: 399563 | X25: 78099 | Y25: 4531238 | Z25: 2931400 | AA25: 20626200 | AB25: 21992200 | AC25: 17609700 | AD25: 1190900 | AE25: 29413097472 | AF25: 13191326720
A26: 04/05/2026 | E26: 22593000 | J26: 21802173 | N26: 13322300 | O26: 2063500 | P26: 2781100 | Z26: 2931400 | AA26: 20626200 | AB26: 21992200 | AC26: 17609700 | AD26: 1190900 | AE26: 16917640192 | AF26: 7425126400
A27: 04/04/2026 | E27: 22593000 | J27: 25588054 | N27: 13322300 | O27: 2063500 | P27: 2781100 | Z27: 2931400 | AA27: 20626200 | AB27: 21992200 | AC27: 17609700 | AD27: 1190900 | AE27: 18723545088 | AF27: 7981454336
A28: 04/03/2026 | B28: 82232 | C28: 350806 | D28: 57982 | E28: 22308300 | J28: 63006749 | K28: 1031109 | L28: 146920 | M28: 351460 | N28: 13321600 | O28: 2063500 | P28: 2781100 | Q28: 52462 | R28: 2829623 | S28: 320161 | T28: 104653 | U28: 15177459 | V28: 4226690 | W28: 340253 | X28: 79058 | Y28: 2642764 | Z28: 2920200 | AA28: 20574000 | AB28: 21988700 | AC28: 17579000 | AD28: 1190900 | AE28: 33710342144 | AF28: 14650299392
A29: 04/02/2026 | B29: 121893 | C29: 315800 | D29: 73617 | E29: 41018800 | J29: 65735760 | K29: 2700503 | L29: 477392 | M29: 418579 | N29: 3270900 | O29: 2604700 | P29: 3137500 | Q29: 42320 | R29: 4260492 | S29: 631653 | T29: 355715 | U29: 11287955 | V29: 6007941 | W29: 389536 | X29: 288024 | Y29: 4282178 | Z29: 4394300 | AA29: 31957500 | AB29: 30889900 | AC29: 15322400 | AD29: 2038500 | AE29: 38034984960 | AF29: 21228568576
A30: 04/01/2026 | B30: 119413 | C30: 334739 | D30: 59417 | E30: 36601200 | J30: 65833723 | K30: 2227889 | L30: 322432 | M30: 776563 | N30: 4953200 | O30: 2971600 | P30: 3891700 | Q30: 15563 | R30: 3296510 | S30: 638836 | T30: 143423 | U30: 14192936 | V30: 5294606 | W30: 512423 | X30: 209312 | Y30: 3891040 | Z30: 6044000 | AA30: 30403300 | AB30: 30822200 | AC30: 21171200 | AD30: 2594900 | AE30: 42860240896 | AF30: 21609723904
A31: 03/31/2026 | B31: 111161 | C31: 261636 | D31: 58133 | E31: 18921800 | J31: 62567301 | K31: 2681930 | L31: 306951 | M31: 1169585 | N31: 2658900 | O31: 1878500 | P31: 3631300 | Q31: 15317 | R31: 5046064 | S31: 574253 | T31: 159359 | U31: 14489654 | V31: 6013508 | W31: 354888 | X31: 229162 | Y31: 4385174 | Z31: 3795600 | AA31: 30473100 | AB31: 24676900 | AC31: 15733900 | AD31: 1687100 | AE31: 36121321472 | AF31: 16955199488
A32: 03/30/2026 | B32: 206208 | C32: 279596 | D32: 108762 | E32: 19536200 | J32: 45889793 | K32: 1980294 | L32: 279590 | M32: 490917 | N32: 3487800 | O32: 2903300 | P32: 4460400 | Q32: 21992 | R32: 2659413 | S32: 716663 | T32: 427931 | U32: 14170834 | V32: 5192705 | W32: 356885 | X32: 164933 | Y32: 2882542 | Z32: 4885200 | AA32: 23383200 | AB32: 29997400 | AC32: 21430100 | AD32: 1698400 | AE32: 28135385088 | AF32: 13332261888
A33: 03/29/2026 | E33: 19536200 | J33: 23042241 | N33: 3487800 | O33: 2903300 | P33: 4460400 | Z33: 4885200 | AA33: 23383200 | AB33: 29997400 | AC33: 21430100 | AD33: 1698400 | AE33: 19881410560 | AF33: 8541316608
A34: 03/28/2026 | E34: 19536200 | J34: 78785399 | N34: 3487800 | O34: 2903300 | P34: 4460400 | Z34: 4885200 | AA34: 23383200 | AB34: 29997400 | AC34: 21430100 | AD34: 1698400 | AE34: 44203380736 | AF34: 18178652160
A35: 03/27/2026 | B35: 203190 | C35: 357094 | D35: 103758 | E35: 17337800 | J35: 73946475 | K35: 1681295 | L35: 181664 | M35: 419605 | N35: 2800100 | O35: 2351400 | P35: 2622100 | Q35: 8099 | R35: 2320741 | S35: 440575 | T35: 342870 | U35: 8381359 | V35: 5322600 | W35: 381593 | X35: 265419 | Y35: 3800142 | Z35: 4652300 | AA35: 20173000 | AB35: 10900100 | AC35: 15216700 | AD35: 1207500 | AE35: 38136483840 | AF35: 17662779392
A36: 03/26/2026 | B36: 499077 | C36: 282058 | D36: 109371 | E36: 14560702 | J36: 42778470 | K36: 1603454 | L36: 104924 | M36: 242585 | N36: 2331946 | O36: 2727962 | P36: 2406190 | Q36: 11311 | R36: 3624896 | S36: 330962 | T36: 220672 | U36: 12538661 | V36: 3931171 | W36: 414748 | X36: 200882 | Y36: 3857783 | Z36: 3107264 | AA36: 26737815 | AB36: 25321504 | AC36: 18514805 | AD36: 1246277 | AE36: 35343937536 | AF36: 16755169280
A37: 03/25/2026 | B37: 383412 | C37: 248491 | D37: 93184 | E37: 16986969 | J37: 43729633 | K37: 2606646 | L37: 121044 | M37: 267847 | N37: 3614435 | O37: 4330497 | P37: 4138516 | Q37: 13444 | R37: 3404393 | S37: 441962 | T37: 117972 | U37: 10318232 | V37: 4447748 | W37: 320855 | X37: 129420 | Y37: 3258600 | Z37: 4030048 | AA37: 29661242 | AB37: 31394691 | AC37: 18977958 | AD37: 1444286 | AE37: 41029095424 | AF37: 18535809024
A38: 03/24/2026 | B38: 412611 | C38: 252742 | D38: 86174 | E38: 29629090 | J38: 74311795 | K38: 2962071 | L38: 198657 | M38: 219975 | N38: 7553645 | O38: 5234387 | P38: 2938590 | Q38: 12632 | R38: 3672485 | S38: 1365641 | T38: 269121 | U38: 13980719 | V38: 4407384 | W38: 489001 | X38: 188269 | Y38: 3402519 | Z38: 4458633 | AA38: 32923717 | AB38: 33676536 | AC38: 20076030 | AD38: 2072355 | AE38: 48975613952 | AF38: 27863912448
A39: 03/23/2026 | B39: 417529 | C39: 279800 | D39: 92432 | E39: 22176491 | J39: 47842126 | K39: 5400365 | L39: 183948 | M39: 490123 | N39: 3001950 | O39: 17568501 | P39: 2931598 | Q39: 28358 | R39: 4664957 | S39: 956968 | T39: 454026 | U39: 16558026 | V39: 7131738 | W39: 466502 | X39: 331009 | Y39: 5880297 | Z39: 5232434 | AA39: 27317421 | AB39: 19058282 | AC39: 28568296 | AD39: 1618669 | AE39: 31928903680 | AF39: 15181412352
A40: 03/22/2026 | E40: 22176491 | J40: 51073664 | N40: 3001950 | O40: 17568501 | P40: 2920149 | Z40: 5193645 | AA40: 27317421 | AB40: 19058282 | AC40: 28004943 | AD40: 1618669 | AE40: 25447782400 | AF40: 12517040128
...

Sheet Summary
A1: Now | B1: Total | C1: Susie | D1: D&B | E1: Jintae | F1: Hyunhee | H1: Crypto | I1: Cash | J1: Gold | K1: Kor stock | L1: US stock | M1: US bonds | O1: Crypto | P1: Cash | Q1: Gold | R1: Kor stock | S1: US stock | T1: US bonds
A2: =NOW() | B2: =Admin!D5 | C2: =Admin!D1 | D2: =Admin!D2 | E2: =Admin!D3 | F2: =Admin!D4 | H2: =SUM(Admin!D8,Admin!D9,Admin!D36,Admin!D37,Admin!D48,Admin!D49) | I2: =SUM(Admin!D10,Admin!D11,Admin!D12,Admin!D21,Admin!D22,Admin!D23,Admin!D24,Admin!D38,Admin!D39,Admin!D40,Admin!D50,Admin!D51,Admin!D52) | J2: =SUM(Admin!D13,Admin!D25,Admin!D53) | K2: =SUM(Admin!D14,Admin!D26,Admin!D27,Admin!D41,Admin!D54) | L2: =SUM(Admin!D15,Admin!D16,Admin!D29,Admin!D30,Admin!D42,Admin!D55) | M2: =SUM(Admin!D17,Admin!D31,Admin!D32,Admin!D43,Admin!D44,Admin!D56) | P2: =SUM(Admin!D21,Admin!D22,Admin!D23,Admin!D24) | Q2: =Admin!D25 | R2: =SUM(Admin!D26,Admin!D27) | S2: =SUM(Admin!D29,Admin!D30) | T2: =SUM(Admin!D31,Admin!D32)
A3: Date | B3: Total | C3: Susie | D3: D&B | E3: Jintae | F3: Hyunhee | H3: Crypto | I3: Cash | J3: Gold | K3: Kor stock | L3: US stock | M3: US bonds | O3: Crypto | P3: Cash | Q3: Gold | R3: Kor stock | S3: US stock | T3: US bonds
A4: 46141 | B4: 5955286830 | C4: 610620296 | D4: 4225605987 | E4: 874563337 | F4: 244497209 | H4: 278443272 | I4: 2090501916 | J4: 476514080 | K4: 874939140 | L4: 1385352089 | M4: 849536332 | O4: 0 | P4: 1700208931 | Q4: 385325185 | R4: 390468980 | S4: 1184344859 | T4: 565258032
A5: 46140 | B5: 5959655561 | C5: 609360111 | D5: 4225354560 | E5: 880751735 | F5: 244189156 | H5: 275975559 | I5: 2064538169 | J5: 481010240 | K5: 902237440 | L5: 1388816711 | M5: 847077443 | O5: 0 | P5: 1674425371 | Q5: 388960930 | R5: 410855585 | S5: 1187376056 | T5: 563736618
A6: 46139 | B6: 5968659631 | C6: 613778955 | D6: 4228605300 | E6: 880943111 | F6: 245332265 | H6: 279339583 | I6: 2062593023 | J6: 487478400 | K6: 903546205 | L6: 1387611154 | M6: 848091266 | O6: 0 | P6: 1672287945 | Q6: 394191300 | R6: 412369505 | S6: 1185839434 | T6: 563917116
A7: 46138 | B7: 5971587370 | C7: 615511690 | D7: 4232313878 | E7: 878261631 | F7: 245500171 | H7: 281696141 | I7: 2067144960 | J7: 490160320 | K7: 889766405 | L7: 1390506435 | M7: 852313109 | O7: 0 | P7: 1676431029 | Q7: 396359990 | R7: 403891760 | S7: 1189820715 | T7: 565810384
A8: 46137 | B8: 5969707487 | C8: 614099171 | D8: 4232313878 | E8: 877972157 | F8: 245322281 | H8: 279816257 | I8: 2067144960 | J8: 490160320 | K8: 889766405 | L8: 1390506435 | M8: 852313109 | O8: 0 | P8: 1676431029 | Q8: 396359990 | R8: 403891760 | S8: 1189820715 | T8: 565810384
A9: 46136 | B9: 5973758772 | C9: 616235572 | D9: 4233576488 | E9: 878371114 | F9: 245575598 | H9: 282604843 | I9: 2073342100 | J9: 490160320 | K9: 889766405 | L9: 1383880152 | M9: 854004952 | O9: 0 | P9: 1682628079 | Q9: 396359990 | R9: 403891760 | S9: 1183194432 | T9: 567502227
A10: 46135 | B10: 5960402817 | C10: 613662279 | D10: 4227776516 | E10: 874651461 | F10: 244312560 | H10: 281195561 | I10: 2069262162 | J10: 493078880 | K10: 881463355 | L10: 1382898069 | M10: 852504790 | O10: 0 | P10: 1679463978 | Q10: 398720035 | R10: 399394510 | S10: 1183184529 | T10: 567013465
A11: 46134 | B11: 5945834827 | C11: 614655944 | D11: 4206959821 | E11: 880252512 | F11: 243966550 | H11: 282610693 | I11: 2067540653 | J11: 497575040 | K11: 886298110 | L11: 1362035439 | M11: 849774892 | O11: 0 | P11: 1677167265 | Q11: 402355780 | R11: 398706760 | S11: 1164166449 | T11: 564563567
A12: 46133 | B12: 5915827806 | C12: 601999026 | D12: 4196768513 | E12: 874399061 | F12: 242661206 | H12: 258624238 | I12: 2061715391 | J12: 497732800 | K12: 890548480 | L12: 1358830804 | M12: 848376093 | O12: 0 | P12: 1670733741 | Q12: 402483350 | R12: 398263715 | S12: 1161695089 | T12: 563592618
A13: 46132 | B13: 5927125692 | C13: 599173129 | D13: 4208212825 | E13: 877444605 | F13: 242295134 | H13: 255047861 | I13: 2067140158 | J13: 500335840 | K13: 886995330 | L13: 1366453320 | M13: 851153183 | O13: 0 | P13: 1676258297 | Q13: 404588255 | R13: 391690625 | S13: 1169603865 | T13: 566071783
A14: 46131 | B14: 5910450917 | C14: 599867026 | D14: 4185970883 | E14: 882608543 | F14: 242004465 | H14: 256870394 | I14: 2057281387 | J14: 502465600 | K14: 890199210 | L14: 1357223255 | M14: 846411071 | O14: 0 | P14: 1667228871 | Q14: 406310450 | R14: 389335090 | S14: 1161127250 | T14: 561969221
A15: 46130 | B15: 5916190955 | C15: 604184532 | D15: 4185970883 | E15: 883419538 | F15: 242616003 | H15: 262610432 | I15: 2057281386 | J15: 502465600 | K15: 890199210 | L15: 1357223255 | M15: 846411071 | O15: 0 | P15: 1667228871 | Q15: 406310450 | R15: 389335090 | S15: 1161127250 | T15: 561969221
... A122: 46023 | B122: 5507085761 | C122: 611193530 | D122: 3853716361 | E122: 808056428 | F122: 234119441 | H122: 300503613 | I122: 1963297235 | J122: 457234820 | K122: 678147230 | L122: 1278619487 | M122: 829283375 | O122: 0 | P122: 1580231634 | Q122: 370016785 | R122: 259644460 | S122: 1093480337 | T122: 550343145

Sheet Admin
A1: Susie | D1: =D18
A2: D&B | D2: =D33
A3: Jintae | D3: =D45
A4: Hyunhee | D4: =D57
A5: Total | D5: =SUM(D1:D4)
T6: 0.2
A7: Susie | D7: KRW value | E7: Stock # | F7: Upbit/케이뱅크 | G7: Binance | H7: 삼성종합 | I7: 삼성ISA | J7: 삼성연금 | K7: 삼성CMA | L7: 대여금 | N7: Stock price | O7: Fiat rate | R7: Guide % | S7: In conventional | T7: Actual % | U7: To rebalance
A8: Crypto | B8: Bitcoin | D8: =E8*N8*O8 | E8: =SUM(F8:L8) | F8: 0.57807519 | G8: 1.2136273 | N8: =Info!E33 | O8: =Info!E11 | R8: =T8 | T8: =D8/$D$18 | U8: =D$18*(R8-T8)
A9: Crypto | B9: Ethereum | D9: =E9*N9*O9 | E9: =SUM(F9:L9) | F9: 0.70705698 | G9: 0.75036428 | N9: =Info!E34 | O9: =O8 | R9: =T9 | T9: =D9/$D$18 | U9: =D$18*(R9-T9)
A10: Cash | B10: KRW | D10: =E10*N10*O10 | E10: =SUM(F10:L10) | F10: 2138003 | H10: 3200 | I10: 24845 | J10: 5883 | L10: 50000000 | N10: 1 | O10: 1 | U10: =(R10-T10)*$D$18
A11: Cash | B11: TIGER CD1년금리액티브(합성) | D11: =E11*N11*O11 | E11: =SUM(F11:L11) | H11: 64 | N11: =Info!E4 | O11: 1 | R11: =(100%-R$8-R$9)*S11 | S11: 0.3 | T11: =(D12+D10+D11)/$D$18 | U11: =(R11-T11)*$D$18
A12: Cash | B12: USDT | D12: =E12*N12*O12 | E12: =SUM(F12:L12) | G12: 10.893838 | N12: 1 | O12: =O8 | R12: =(100%-R$8-R$9)*S12 | S12: 0 | T12: =D12/$D$18 | U12: =(R12-T12)*$D$18
A13: Gold | B13: KINDEX KRX금현물 | D13: =E13*N13*O13 | E13: =SUM(F13:L13) | H13: 1324 | I13: 1053 | N13: =Info!E13 | O13: 1 | Q13: =U13/N13 | R13: =(100%-R$8-R$9)*S13 | S13: 0.2 | T13: =D13/$D$18 | U13: =(R13-T13)*$D$18
A14: Kor Stock | B14: TIGER KOSDAQ150 | D14: =E14*N14*O14 | E14: =SUM(H14:L14) | H14: 2029 | N14: =Info!E20 | O14: 1 | Q14: =U14/N14 | R14: =(100%-R$8-R$9)*S14 | S14: 0.1 | T14: =D14/$D$18 | U14: =(R14-T14)*$D$18
A15: US Stock | B15: ACE 미국S&P500 | D15: =E15*N15*O15 | E15: =SUM(F15:L15) | I15: 807 | N15: =Info!E21 | O15: 1 | Q15: =U15/N15 | R15: =(100%-R$8-R$9)*S15 | S15: 0.05 | T15: =D15/$D$18 | U15: =(R15-T15)*$D$18
A16: US Stock | B16: KODEX 미국나스닥100(TR) | D16: =E16*N16*O16 | E16: =SUM(F16:L16) | H16: 2425 | J16: 56 | N16: =Info!E24 | O16: 1 | Q16: =U16/N16 | R16: =(100%-R$8-R$9)*S16 | S16: 0.15 | T16: =D16/$D$18 | U16: =(R16-T16)*$D$18
A17: US Bonds | B17: ACE 미국장기채액티브 | D17: =E17*N17*O17 | E17: =SUM(F17:L17) | I17: 4418 | J17: 3578 | N17: =Info!E15 | O17: 1 | Q17: =U17/N17 | R17: =(100%-R$8-R$9)*S17 | S17: 0.2 | T17: =D17/$D$18 | U17: =(R17-T17)*$D$18
D18: =SUM(D8:D17) | R18: =SUM(R8:R17) | S18: =SUM(S10:S17) | T18: =D18/$D$18
A20: Dirac & Broglie | D20: KRW value | E20: Stock # | H20: 한투종합 | I20: 한투CMA | N20: Stock price | O20: Fiat rate | R20: Guide % | T20: Actual %
A21: Cash | B21: KRW | D21: =E21*N21*O21 | E21: =SUM(H21:L21) | H21: 245959838 | I21: 0 | N21: 1 | O21: 1
A22: Cash | B22: TIGER CD1년금리액티브(합성) | D22: =E22*N22*O22 | E22: =SUM(H22:L22) | H22: 197 | N22: =N11 | O22: 1 | Q22: =U22/O22/N22 | R22: 0.05 | S22: 0.13 | T22: =(D21+D22)/$D$33 | U22: =$D$33*(R22-T22)
A23: Cash | B23: USD | D23: =E23*N23*O23 | E23: =SUM(H23:L23) | H23: 317 | N23: 1 | O23: =Info!E12 | U23: =$D$33*(R23-T23)
A24: Cash | B24: STRC | D24: =E24*N24*O24 | E24: =SUM(H24:L24) | H24: 8434 | N24: =Info!E8 | O24: =O23 | Q24: =U24/O24/N24 | R24: 0.35 | S24: 0.22 | T24: =SUM(D23,D24)/D33 | U24: =$D$33*(R24-T24)
A25: Gold | B25: KINDEX KRX금현물 | D25: =E25*N25*O25 | E25: =SUM(H25:L25) | H25: 12757 | N25: =N13 | O25: 1 | Q25: =U25/O25/N25 | R25: =S25*(100%-$R$22-$R$24)/(100%-$S$22-$S$24) | S25: 0.1 | T25: =D25/$D$33 | U25: =$D$33*(R25-T25)
A26: Kor Stock | B26: KBSTAR 200 Total Return | D26: =E26*N26*O26 | E26: =SUM(H26:L26) | H26: 3428 | N26: =Info!E22 | O26: 1 | Q26: =U26/O26/N26 | R26: =S26*(100%-$R$22-$R$24)/(100%-$S$22-$S$24) | S26: 0.05 | T26: =D26/$D$33 | U26: =$D$33*(R26-T26)
A27: Kor Stock | B27: TIGER KOSDAQ150 | D27: =E27*N27*O27 | E27: =SUM(H27:L27) | H27: 7050 | N27: =N14 | O27: 1 | Q27: =U27/O27/N27 | R27: =S27*(100%-$R$22-$R$24)/(100%-$S$22-$S$24) | S27: 0.05 | T27: =(D27+D28)/$D$33 | U27: =$D$33*(R27-T27)
A28: Kor Stock | B28: KoAct 코스닥액티브 | D28: =E28*N28*O28 | E28: =SUM(H28:L28) | H28: 3500 | N28: =Info!E27 | O28: 1
A29: US Stock | B29: QQQM | D29: =E29*N29*O29 | E29: =SUM(H29:L29) | H29: 1996 | N29: =Info!E28 | O29: =O23 | Q29: =U29/O29/N29 | R29: =S29*(100%-$R$22-$R$24)/(100%-$S$22-$S$24) | S29: 0.2 | T29: =D29/$D$33 | U29: =$D$33*(R29-T29)
A30: US Stock | B30: SCHD | D30: =E30*N30*O30 | E30: =SUM(H30:L30) | H30: 8342 | N30: =Info!E29 | O30: =O23 | Q30: =U30/O30/N30 | R30: =S30*(100%-$R$22-$R$24)/(100%-$S$22-$S$24) | S30: 0.1 | T30: =D30/$D$33 | U30: =$D$33*(R30-T30)
A31: US Bonds | B31: VTIP | D31: =E31*N31*O31 | E31: =SUM(H31:L31) | H31: 3580 | N31: =Info!E18 | O31: =O23 | Q31: =U31/O31/N31 | R31: =S31*(100%-$R$22-$R$24)/(100%-$S$22-$S$24) | S31: 0.07 | T31: =D31/$D$33 | U31: =$D$33*(R31-T31)
A32: US Bonds | B32: VGLT | D32: =E32*N32*O32 | E32: =SUM(H32:L32) | H32: 3663 | N32: =Info!E17 | O32: =O23 | Q32: =U32/O32/N32 | R32: =S32*(100%-$R$22-$R$24)/(100%-$S$22-$S$24) | S32: 0.08 | T32: =D32/$D$33 | U32: =$D$33*(R32-T32)
D33: =SUM(D21:D32) | R33: =SUM(R21:R32) | S33: =SUM(S21:S32) | T33: =SUM(T21:T32)
A35: Jintae | D35: KRW value | E35: Stock # | F35: Upbit | G35: Binance | H35: 삼성종합 | I35: 삼성ISA | J35: 삼성CMA | K35: 미래연금 | L35: 미래IRP | N35: Stock price | O35: Fiat rate | R35: Guide % | T35: Actual %
A36: Crypto | B36: Bitcoin | D36: =E36*N36*O36 | E36: =SUM(F36:L36) | F36: 0.16849539 | G36: 0.10870189 | N36: =N8 | O36: =O8 | R36: =T36 | T36: =D36/$D$45 | U36: =(R36-T36)*$D$45
A37: Crypto | B37: Ethereum | D37: =E37*N37*O37 | E37: =SUM(F37:L37) | F37: 2.578812 | G37: 0.79480734 | N37: =N9 | O37: =O8 | R37: =T37 | T37: =D37/$D$45 | U37: =(R37-T37)*$D$45
A38: Cash | B38: KODEX KOFR금리액티브(합성) | D38: =E38*N38*O38 | E38: =SUM(F38:L38) | K38: 354 | L38: 973 | N38: =Info!E2 | O38: 1
A39: Cash | B39: TIGER MSCI US 리츠(합성H) | D39: =E39*N39*O39 | E39: =SUM(F39:L39) | H39: 4095 | N39: =Info!E19 | O39: 1
A40: Cash | B40: KRW | D40: =E40*N40*O40 | E40: =SUM(F40:L40) | H40: 0 | I40: 1721690 | J40: 0 | K40: 17077 | L40: 1596 | N40: 1 | O40: 1 | R40: =(100%-R$36-R$37)*S40 | S40: 0.25 | T40: =(D38+D40+D39)/$D$45 | U40: =(R40-T40)*$D$45
A41: Kor Stock | B41: 유비케어 | D41: =E41*N41*O41 | E41: =SUM(F41:L41) | H41: =64909+14365 | I41: 22305 | N41: =Info!E26 | O41: 1 | Q41: =U41/N41/O41 | R41: =(100%-R$36-R$37)*S41 | S41: 0.5 | T41: =D41/$D$45 | U41: =(R41-T41)*$D$45
A42: US Stock | B42: KODEX 미국나스닥100(TR) | D42: =E42*N42*O42 | E42: =SUM(F42:L42) | K42: 1656 | N42: =N16 | O42: 1 | Q42: =U42/N42/O42 | R42: =(100%-R$36-R$37)*S42 | S42: 0.05 | T42: =D42/$D$45 | U42: =(R42-T42)*$D$45
...

Sheet D&B
E3: D&B
B4: Borrowings | E4: Jintae | F4: Hyunhee | G4: Susie
C5: 0.006 | D5: =4.6%-C5 | E5: 0.1 | F5: 0.4 | G5: 0.5
A6: Jintae | B6: =400000000+900000000+400000000 | C6: =B6*$C$5 | D6: =B6*$D$5 | F6: =$D6*F$5 | G6: =$D6*G$5
A7: Hyunhee | B7: =1600000000+900000000+200000000 | C7: =B7*$C$5 | D7: =B7*$D$5 | E7: =$D7*E$5 | G7: =$D7*G$5
A8: Susie | B8: =100000000+100000000+400000000 | C8: =B8*$C$5 | D8: =B8*$D$5 | E8: =$D8*E$5 | F8: =$D8*F$5
A9: Total | B9: =B6+B7+B8 | C9: =C6+C7+C8 | D9: =D6+D7+D8 | E9: =E6+E7+E8 | F9: =F6+F7+F8 | G9: =G6+G7+G8
